Workbook

Sheet 🏠 Accueil
A1: TECHNOLOGIE 5e Progression annuelle 2026-2027 · Académie de Martinique
A5: Programme 2024 (BO n°9 du 29/02/2024) · 1 h 30 / semaine · cahier Nathan 5e (éd. 2024) · ressources en ligne du dépôt « En ligne pour le cycle 4 »
B7: 📊 L'année en un coup d'œil
B8: 37 | D8: ='🧭 Progression'!G11 -> 29 | F8: 8
B9: Semaines de cours | D9: Séances planifiées | F9: Semaines tampon (aléas)
B11: 7 | D11: 38 | F11: 2 (+1 partielle)
B12: Séquences | D12: Codes 5e travaillés | F12: Séquences déjà en ligne
B14: 🧭 Naviguer dans le classeur (cliquer)
B15: ▸ 📅 Calendrier | C15: 37 semaines, vacances, fériés, tampons, aléas | E15: ▸ 🗓 Frise de l'année | F15: les 7 séquences posées sur l'année (vue gantt)
B16: ▸ 📚 Référentiel Cycle 4 | C16: C1 → C9 : les 114 sous-compétences du cycle | E16: ▸ 📗 Référentiel 5e | F16: les 38 sous-compétences du niveau
B17: ▸ 🧭 Progression | C17: les 7 séquences : codes, répartition 🏫🏠🔁, ressources | E17: ▸ S1 | F17: Environnement numérique — IA Thème 1 (canevas)
B18: ▸ S2 | C18: Comparer pour choisir — IA Thème 1 (canevas) | E18: ▸ S3 | F18: Chaîne d'énergie — IA Th.1 + Fable (canevas + lampadaire)
B19: ▸ S4 | C19: Lampadaire (1) : information, données, programmes — ✅ rempli | E19: ▸ S5 | F19: Lampadaire (2) : réseau local — ✅ rempli
B20: ▸ S6 | C20: SOS panne — pré-rempli (ressources 🔜) | E20: ▸ S7 | F20: Mini-projet — IA Thème 3 (canevas)
B22: 📖 Mode d'emploi express
B23: 🏫 / 🏠 / 🔁 | C23: En classe (matériel, collectif, évaluations) · À la maison (QCM, synthèses, simulateurs — corrections intégrées, faisables sur téléphone) · Hybride/classe inversée (lancement en classe, simulateur à la maison, exploitation au retour).
B24: ⏳ Tampons | C24: 8 semaines NON planifiées absorbent les aléas. NOUVEAU — moteur automatique : dans 📅 Calendrier, colonne « ⚠ Imprévu ? », choisis l'imprévu dans le menu de la semaine touchée (absence, sortie, Fête de la science, ERASMUS…) : toutes les séances se décalent d'une semaine, la frise et la progression se recalculent, et la réserve de fin d'année absorbe le décalage. Au-delà de 8 imprévus, une alerte 🛑 s'affiche.
B25: 📋 Cahier de texte | C25: Dans chaque générateur, les blocs jaunes sont prêts à copier-coller dans Pronote : « Contenu de la séance » + « Travail à faire » (lien direct, durée estimée, mention téléphone).
B26: ✅ 🔜 📘 | C26: Ressource en ligne · à produire · cahier Nathan (filet de sécurité sans connexion). Chaque IA de thème remplit les générateurs de SES séquences — canevas à entériner au Conseil du 28/07.
B27: 📆 Calendrier | C27: Rectorat de Martinique 2026-2027 : rentrée mar. 1/09 · Toussaint 20/10→3/11 · Noël 19/12→4/01 · Carnaval 6→22/02 · Pâques 20/04→3/05 · fin des cours 3/07. À confirmer sur ac-martinique.fr.
B29: Classeur généré par Fable (IA du Thème 2) — dépôt : https://pll-process.github.io/en-ligne-pour-le-cycle-4/

Sheet 📅 Calendrier
A1: CALENDRIER 5e — année scolaire 2026-2027 (académie de Martinique) — 1 séance de 1 h 30 par semaine
D2: =IF(COUNTIF($G$4:$G$44,"<>")>8,"🛑 "&COUNTIF($G$4:$G$44,"<>")&" imprévus : la réserve (8) est dépassée — des séances sortent de l'année, arbitrage nécessaire !","✔ Réserve d'aléas : "&(8-COUNTIF($G$4:$G$44,"<>"))&" semaine(s) tampon restante(s) sur 8") -> ✔ Réserve d'aléas : 8 semaine(s) tampon restante(s) sur 8 | F2: ◀ Accueil
A3: Sem. | B3: Lundi de la semaine | C3: Période | D3: Affectation (séquence · séance) | E3: Repères / jours fériés | F3: Aléas / notes (à remplir) | G3: ⚠ Imprévu ? (menu déroulant) | H3: n° créneau (auto)
A4: S01 | B4: 31/08/2026 | C4: P1 | D4: =IF($G4<>"",$G4&" — les séances suivantes se décalent d'une semaine",INDEX('⚙ Moteur'!$B$5:$B$41,$H4)) -> S1 · séance 1 | E4: Rentrée des élèves mardi 1er septembre. | H4: =IF($G4<>"",0,0+1) -> 1
A5: S02 | B5: 07/09/2026 | C5: P1 | D5: =IF($G5<>"",$G5&" — les séances suivantes se décalent d'une semaine",INDEX('⚙ Moteur'!$B$5:$B$41,$H5)) -> S1 · séance 2 | H5: =IF($G5<>"",H4,H4+1) -> 2
A6: S03 | B6: 14/09/2026 | C6: P1 | D6: =IF($G6<>"",$G6&" — les séances suivantes se décalent d'une semaine",INDEX('⚙ Moteur'!$B$5:$B$41,$H6)) -> S1 · séance 3 | H6: =IF($G6<>"",H5,H5+1) -> 3
A7: S04 | B7: 21/09/2026 | C7: P1 | D7: =IF($G7<>"",$G7&" — les séances suivantes se décalent d'une semaine",INDEX('⚙ Moteur'!$B$5:$B$41,$H7)) -> S2 · séance 1 | H7: =IF($G7<>"",H6,H6+1) -> 4
A8: S05 | B8: 28/09/2026 | C8: P1 | D8: =IF($G8<>"",$G8&" — les séances suivantes se décalent d'une semaine",INDEX('⚙ Moteur'!$B$5:$B$41,$H8)) -> S2 · séance 2 | H8: =IF($G8<>"",H7,H7+1) -> 5
A9: S06 | B9: 05/10/2026 | C9: P1 | D9: =IF($G9<>"",$G9&" — les séances suivantes se décalent d'une semaine",INDEX('⚙ Moteur'!$B$5:$B$41,$H9)) -> S2 · séance 3 | H9: =IF($G9<>"",H8,H8+1) -> 6
A10: S07 | B10: 12/10/2026 | C10: P1 | D10: =IF($G10<>"",$G10&" — les séances suivantes se décalent d'une semaine",INDEX('⚙ Moteur'!$B$5:$B$41,$H10)) -> S2 · séance 4 | H10: =IF($G10<>"",H9,H9+1) -> 7
A11: S08 | B11: 19/10/2026 | C11: P1 | D11: =IF($G11<>"",$G11&" — les séances suivantes se décalent d'une semaine",INDEX('⚙ Moteur'!$B$5:$B$41,$H11)) -> ⏳ TAMPON P1 — rattrapage / remédiation | H11: =IF($G11<>"",H10,H10+1) -> 8
A12: 🏖 Vacances de la Toussaint : 20/10 → 3/11
A13: S09 | B13: 02/11/2026 | C13: P2 | D13: =IF($G13<>"",$G13&" — les séances suivantes se décalent d'une semaine",INDEX('⚙ Moteur'!$B$5:$B$41,$H13)) -> S3 · séance 1 | H13: =IF($G13<>"",H11,H11+1) -> 9
A14: S10 | B14: 09/11/2026 | C14: P2 | D14: =IF($G14<>"",$G14&" — les séances suivantes se décalent d'une semaine",INDEX('⚙ Moteur'!$B$5:$B$41,$H14)) -> S3 · séance 2 | E14: Mer. 11/11 férié (Armistice) | H14: =IF($G14<>"",H13,H13+1) -> 10
A15: S11 | B15: 16/11/2026 | C15: P2 | D15: =IF($G15<>"",$G15&" — les séances suivantes se décalent d'une semaine",INDEX('⚙ Moteur'!$B$5:$B$41,$H15)) -> S3 · séance 3 | H15: =IF($G15<>"",H14,H14+1) -> 11
A16: S12 | B16: 23/11/2026 | C16: P2 | D16: =IF($G16<>"",$G16&" — les séances suivantes se décalent d'une semaine",INDEX('⚙ Moteur'!$B$5:$B$41,$H16)) -> S3 · séance 4 | H16: =IF($G16<>"",H15,H15+1) -> 12
A17: S13 | B17: 30/11/2026 | C17: P2 | D17: =IF($G17<>"",$G17&" — les séances suivantes se décalent d'une semaine",INDEX('⚙ Moteur'!$B$5:$B$41,$H17)) -> S4 · séance 1 | H17: =IF($G17<>"",H16,H16+1) -> 13
A18: S14 | B18: 07/12/2026 | C18: P2 | D18: =IF($G18<>"",$G18&" — les séances suivantes se décalent d'une semaine",INDEX('⚙ Moteur'!$B$5:$B$41,$H18)) -> S4 · séance 2 | H18: =IF($G18<>"",H17,H17+1) -> 14
A19: S15 | B19: 14/12/2026 | C19: P2 | D19: =IF($G19<>"",$G19&" — les séances suivantes se décalent d'une semaine",INDEX('⚙ Moteur'!$B$5:$B$41,$H19)) -> ⏳ TAMPON P2 — rattrapage / remédiation | H19: =IF($G19<>"",H18,H18+1) -> 15
A20: 🏖 Vacances de Noël : 19/12 → 4/01
A21: S16 | B21: 04/01/2027 | C21: P3 | D21: =IF($G21<>"",$G21&" — les séances suivantes se décalent d'une semaine",INDEX('⚙ Moteur'!$B$5:$B$41,$H21)) -> S4 · séance 3 | H21: =IF($G21<>"",H19,H19+1) -> 16
A22: S17 | B22: 11/01/2027 | C22: P3 | D22: =IF($G22<>"",$G22&" — les séances suivantes se décalent d'une semaine",INDEX('⚙ Moteur'!$B$5:$B$41,$H22)) -> S4 · séance 4 | H22: =IF($G22<>"",H21,H21+1) -> 17
A23: S18 | B23: 18/01/2027 | C23: P3 | D23: =IF($G23<>"",$G23&" — les séances suivantes se décalent d'une semaine",INDEX('⚙ Moteur'!$B$5:$B$41,$H23)) -> S4 · séance 5 | H23: =IF($G23<>"",H22,H22+1) -> 18
A24: S19 | B24: 25/01/2027 | C24: P3 | D24: =IF($G24<>"",$G24&" — les séances suivantes se décalent d'une semaine",INDEX('⚙ Moteur'!$B$5:$B$41,$H24)) -> S5 · séance 1 | H24: =IF($G24<>"",H23,H23+1) -> 19
A25: S20 | B25: 01/02/2027 | C25: P3 | D25: =IF($G25<>"",$G25&" — les séances suivantes se décalent d'une semaine",INDEX('⚙ Moteur'!$B$5:$B$41,$H25)) -> ⏳ TAMPON P3 — rattrapage / remédiation | H25: =IF($G25<>"",H24,H24+1) -> 20
A26: 🏖 Vacances de Carnaval : 6/02 → 22/02
A27: S21 | B27: 22/02/2027 | C27: P4 | D27: =IF($G27<>"",$G27&" — les séances suivantes se décalent d'une semaine",INDEX('⚙ Moteur'!$B$5:$B$41,$H27)) -> S5 · séance 2 | H27: =IF($G27<>"",H25,H25+1) -> 21
A28: S22 | B28: 01/03/2027 | C28: P4 | D28: =IF($G28<>"",$G28&" — les séances suivantes se décalent d'une semaine",INDEX('⚙ Moteur'!$B$5:$B$41,$H28)) -> S5 · séance 3 | H28: =IF($G28<>"",H27,H27+1) -> 22
A29: S23 | B29: 08/03/2027 | C29: P4 | D29: =IF($G29<>"",$G29&" — les séances suivantes se décalent d'une semaine",INDEX('⚙ Moteur'!$B$5:$B$41,$H29)) -> S6 · séance 1 | H29: =IF($G29<>"",H28,H28+1) -> 23
A30: S24 | B30: 15/03/2027 | C30: P4 | D30: =IF($G30<>"",$G30&" — les séances suivantes se décalent d'une semaine",INDEX('⚙ Moteur'!$B$5:$B$41,$H30)) -> S6 · séance 2 | H30: =IF($G30<>"",H29,H29+1) -> 24
A31: S25 | B31: 22/03/2027 | C31: P4 | D31: =IF($G31<>"",$G31&" — les séances suivantes se décalent d'une semaine",INDEX('⚙ Moteur'!$B$5:$B$41,$H31)) -> S6 · séance 3 | E31: Ven. 26/03 férié (Vendredi saint, Martinique) | H31: =IF($G31<>"",H30,H30+1) -> 25
A32: S26 | B32: 29/03/2027 | C32: P4 | D32: =IF($G32<>"",$G32&" — les séances suivantes se décalent d'une semaine",INDEX('⚙ Moteur'!$B$5:$B$41,$H32)) -> S6 · séance 4 | E32: Lun. 29/03 férié (lundi de Pâques) | H32: =IF($G32<>"",H31,H31+1) -> 26
A33: S27 | B33: 05/04/2027 | C33: P4 | D33: =IF($G33<>"",$G33&" — les séances suivantes se décalent d'une semaine",INDEX('⚙ Moteur'!$B$5:$B$41,$H33)) -> S7 · séance 1 | H33: =IF($G33<>"",H32,H32+1) -> 27
A34: S28 | B34: 12/04/2027 | C34: P4 | D34: =IF($G34<>"",$G34&" — les séances suivantes se décalent d'une semaine",INDEX('⚙ Moteur'!$B$5:$B$41,$H34)) -> ⏳ TAMPON P4 — rattrapage / remédiation | H34: =IF($G34<>"",H33,H33+1) -> 28
A35: 🏖 Vacances de Pâques : 20/04 → 3/05
A36: S29 | B36: 03/05/2027 | C36: P5 | D36: =IF($G36<>"",$G36&" — les séances suivantes se décalent d'une semaine",INDEX('⚙ Moteur'!$B$5:$B$41,$H36)) -> S7 · séance 2 | E36: Jeu. 6/05 férié (Ascension) — pont probable ven. 7/05 | H36: =IF($G36<>"",H34,H34+1) -> 29
A37: S30 | B37: 10/05/2027 | C37: P5 | D37: =IF($G37<>"",$G37&" — les séances suivantes se décalent d'une semaine",INDEX('⚙ Moteur'!$B$5:$B$41,$H37)) -> S7 · séance 3 | H37: =IF($G37<>"",H36,H36+1) -> 30
A38: S31 | B38: 17/05/2027 | C38: P5 | D38: =IF($G38<>"",$G38&" — les séances suivantes se décalent d'une semaine",INDEX('⚙ Moteur'!$B$5:$B$41,$H38)) -> S7 · séance 4 | E38: Lun. 17/05 férié (Pentecôte); Ven. 21/05 : veille du 22 mai (abolition, samedi) — commémorations | H38: =IF($G38<>"",H37,H37+1) -> 31
A39: S32 | B39: 24/05/2027 | C39: P5 | D39: =IF($G39<>"",$G39&" — les séances suivantes se décalent d'une semaine",INDEX('⚙ Moteur'!$B$5:$B$41,$H39)) -> S7 · séance 5 | H39: =IF($G39<>"",H38,H38+1) -> 32
A40: S33 | B40: 31/05/2027 | C40: P5 | D40: =IF($G40<>"",$G40&" — les séances suivantes se décalent d'une semaine",INDEX('⚙ Moteur'!$B$5:$B$41,$H40)) -> S7 · séance 6 | H40: =IF($G40<>"",H39,H39+1) -> 33
...

Sheet 🗓 Frise de l'année
A1: FRISE DE L'ANNÉE 5e — se recalcule automatiquement selon les imprévus du Calendrier
B2: ='📅 Calendrier'!D2 -> ✔ Réserve d'aléas : 8 semaine(s) tampon restante(s) sur 8 | P2: ◀ Accueil
C3: P1 (8 sem.) | K3: P2 (7 sem.) | R3: P3 (5 sem.) | W3: P4 (8 sem.) | AE3: P5 (9 sem.)
C4: S01 | D4: S02 | E4: S03 | F4: S04 | G4: S05 | H4: S06 | I4: S07 | J4: S08 | K4: S09 | L4: S10 | M4: S11 | N4: S12 | O4: S13 | P4: S14 | Q4: S15 | R4: S16 | S4: S17 | T4: S18 | U4: S19 | V4: S20 | W4: S21 | X4: S22 | Y4: S23 | Z4: S24 | AA4: S25 | AB4: S26 | AC4: S27 | AD4: S28 | AE4: S29 | AF4: S30 | AG4: S31 | AH4: S32 | AI4: S33 | AJ4: S34 | AK4: S35 | AL4: S36 | AM4: S37
C5: 31/08 | D5: 07/09 | E5: 14/09 | F5: 21/09 | G5: 28/09 | H5: 05/10 | I5: 12/10 | J5: 19/10 | K5: 02/11 | L5: 09/11 | M5: 16/11 | N5: 23/11 | O5: 30/11 | P5: 07/12 | Q5: 14/12 | R5: 04/01 | S5: 11/01 | T5: 18/01 | U5: 25/01 | V5: 01/02 | W5: 22/02 | X5: 01/03 | Y5: 08/03 | Z5: 15/03 | AA5: 22/03 | AB5: 29/03 | AC5: 05/04 | AD5: 12/04 | AE5: 03/05 | AF5: 10/05 | AG5: 17/05 | AH5: 24/05 | AI5: 31/05 | AJ5: 07/06 | AK5: 14/06 | AL5: 21/06 | AM5: 28/06
B6: S1 · Environnement numérique | C6: =IF(LEFT('📅 Calendrier'!$D4,2)="S1",MID('📅 Calendrier'!$D4,SEARCH("séance",'📅 Calendrier'!$D4)+7,2),"") -> 1 | D6: =IF(LEFT('📅 Calendrier'!$D5,2)="S1",MID('📅 Calendrier'!$D5,SEARCH("séance",'📅 Calendrier'!$D5)+7,2),"") -> 2 | E6: =IF(LEFT('📅 Calendrier'!$D6,2)="S1",MID('📅 Calendrier'!$D6,SEARCH("séance",'📅 Calendrier'!$D6)+7,2),"") -> 3 | F6: =IF(LEFT('📅 Calendrier'!$D7,2)="S1",MID('📅 Calendrier'!$D7,SEARCH("séance",'📅 Calendrier'!$D7)+7,2),"") | G6: =IF(LEFT('📅 Calendrier'!$D8,2)="S1",MID('📅 Calendrier'!$D8,SEARCH("séance",'📅 Calendrier'!$D8)+7,2),"") | H6: =IF(LEFT('📅 Calendrier'!$D9,2)="S1",MID('📅 Calendrier'!$D9,SEARCH("séance",'📅 Calendrier'!$D9)+7,2),"") | I6: =IF(LEFT('📅 Calendrier'!$D10,2)="S1",MID('📅 Calendrier'!$D10,SEARCH("séance",'📅 Calendrier'!$D10)+7,2),"") | J6: =IF(LEFT('📅 Calendrier'!$D11,2)="S1",MID('📅 Calendrier'!$D11,SEARCH("séance",'📅 Calendrier'!$D11)+7,2),"") | K6: =IF(LEFT('📅 Calendrier'!$D13,2)="S1",MID('📅 Calendrier'!$D13,SEARCH("séance",'📅 Calendrier'!$D13)+7,2),"") | L6: =IF(LEFT('📅 Calendrier'!$D14,2)="S1",MID('📅 Calendrier'!$D14,SEARCH("séance",'📅 Calendrier'!$D14)+7,2),"") | M6: =IF(LEFT('📅 Calendrier'!$D15,2)="S1",MID('📅 Calendrier'!$D15,SEARCH("séance",'📅 Calendrier'!$D15)+7,2),"") | N6: =IF(LEFT('📅 Calendrier'!$D16,2)="S1",MID('📅 Calendrier'!$D16,SEARCH("séance",'📅 Calendrier'!$D16)+7,2),"") | O6: =IF(LEFT('📅 Calendrier'!$D17,2)="S1",MID('📅 Calendrier'!$D17,SEARCH("séance",'📅 Calendrier'!$D17)+7,2),"") | P6: =IF(LEFT('📅 Calendrier'!$D18,2)="S1",MID('📅 Calendrier'!$D18,SEARCH("séance",'📅 Calendrier'!$D18)+7,2),"") | Q6: =IF(LEFT('📅 Calendrier'!$D19,2)="S1",MID('📅 Calendrier'!$D19,SEARCH("séance",'📅 Calendrier'!$D19)+7,2),"") | R6: =IF(LEFT('📅 Calendrier'!$D21,2)="S1",MID('📅 Calendrier'!$D21,SEARCH("séance",'📅 Calendrier'!$D21)+7,2),"") | S6: =IF(LEFT('📅 Calendrier'!$D22,2)="S1",MID('📅 Calendrier'!$D22,SEARCH("séance",'📅 Calendrier'!$D22)+7,2),"") | T6: =IF(LEFT('📅 Calendrier'!$D23,2)="S1",MID('📅 Calendrier'!$D23,SEARCH("séance",'📅 Calendrier'!$D23)+7,2),"") | U6: =IF(LEFT('📅 Calendrier'!$D24,2)="S1",MID('📅 Calendrier'!$D24,SEARCH("séance",'📅 Calendrier'!$D24)+7,2),"") | V6: =IF(LEFT('📅 Calendrier'!$D25,2)="S1",MID('📅 Calendrier'!$D25,SEARCH("séance",'📅 Calendrier'!$D25)+7,2),"") | W6: =IF(LEFT('📅 Calendrier'!$D27,2)="S1",MID('📅 Calendrier'!$D27,SEARCH("séance",'📅 Calendrier'!$D27)+7,2),"") | X6: =IF(LEFT('📅 Calendrier'!$D28,2)="S1",MID('📅 Calendrier'!$D28,SEARCH("séance",'📅 Calendrier'!$D28)+7,2),"") | Y6: =IF(LEFT('📅 Calendrier'!$D29,2)="S1",MID('📅 Calendrier'!$D29,SEARCH("séance",'📅 Calendrier'!$D29)+7,2),"") | Z6: =IF(LEFT('📅 Calendrier'!$D30,2)="S1",MID('📅 Calendrier'!$D30,SEARCH("séance",'📅 Calendrier'!$D30)+7,2),"") | AA6: =IF(LEFT('📅 Calendrier'!$D31,2)="S1",MID('📅 Calendrier'!$D31,SEARCH("séance",'📅 Calendrier'!$D31)+7,2),"") | AB6: =IF(LEFT('📅 Calendrier'!$D32,2)="S1",MID('📅 Calendrier'!$D32,SEARCH("séance",'📅 Calendrier'!$D32)+7,2),"") | AC6: =IF(LEFT('📅 Calendrier'!$D33,2)="S1",MID('📅 Calendrier'!$D33,SEARCH("séance",'📅 Calendrier'!$D33)+7,2),"") | AD6: =IF(LEFT('📅 Calendrier'!$D34,2)="S1",MID('📅 Calendrier'!$D34,SEARCH("séance",'📅 Calendrier'!$D34)+7,2),"") | AE6: =IF(LEFT('📅 Calendrier'!$D36,2)="S1",MID('📅 Calendrier'!$D36,SEARCH("séance",'📅 Calendrier'!$D36)+7,2),"") | AF6: =IF(LEFT('📅 Calendrier'!$D37,2)="S1",MID('📅 Calendrier'!$D37,SEARCH("séance",'📅 Calendrier'!$D37)+7,2),"") | AG6: =IF(LEFT('📅 Calendrier'!$D38,2)="S1",MID('📅 Calendrier'!$D38,SEARCH("séance",'📅 Calendrier'!$D38)+7,2),"") | AH6: =IF(LEFT('📅 Calendrier'!$D39,2)="S1",MID('📅 Calendrier'!$D39,SEARCH("séance",'📅 Calendrier'!$D39)+7,2),"") | AI6: =IF(LEFT('📅 Calendrier'!$D40,2)="S1",MID('📅 Calendrier'!$D40,SEARCH("séance",'📅 Calendrier'!$D40)+7,2),"") | AJ6: =IF(LEFT('📅 Calendrier'!$D41,2)="S1",MID('📅 Calendrier'!$D41,SEARCH("séance",'📅 Calendrier'!$D41)+7,2),"") | AK6: =IF(LEFT('📅 Calendrier'!$D42,2)="S1",MID('📅 Calendrier'!$D42,SEARCH("séance",'📅 Calendrier'!$D42)+7,2),"") | AL6: =IF(LEFT('📅 Calendrier'!$D43,2)="S1",MID('📅 Calendrier'!$D43,SEARCH("séance",'📅 Calendrier'!$D43)+7,2),"") | AM6: =IF(LEFT('📅 Calendrier'!$D44,2)="S1",MID('📅 Calendrier'!$D44,SEARCH("séance",'📅 Calendrier'!$D44)+7,2),"")
B7: S2 · Comparer pour choisir | C7: =IF(LEFT('📅 Calendrier'!$D4,2)="S2",MID('📅 Calendrier'!$D4,SEARCH("séance",'📅 Calendrier'!$D4)+7,2),"") | D7: =IF(LEFT('📅 Calendrier'!$D5,2)="S2",MID('📅 Calendrier'!$D5,SEARCH("séance",'📅 Calendrier'!$D5)+7,2),"") | E7: =IF(LEFT('📅 Calendrier'!$D6,2)="S2",MID('📅 Calendrier'!$D6,SEARCH("séance",'📅 Calendrier'!$D6)+7,2),"") | F7: =IF(LEFT('📅 Calendrier'!$D7,2)="S2",MID('📅 Calendrier'!$D7,SEARCH("séance",'📅 Calendrier'!$D7)+7,2),"") -> 1 | G7: =IF(LEFT('📅 Calendrier'!$D8,2)="S2",MID('📅 Calendrier'!$D8,SEARCH("séance",'📅 Calendrier'!$D8)+7,2),"") -> 2 | H7: =IF(LEFT('📅 Calendrier'!$D9,2)="S2",MID('📅 Calendrier'!$D9,SEARCH("séance",'📅 Calendrier'!$D9)+7,2),"") -> 3 | I7: =IF(LEFT('📅 Calendrier'!$D10,2)="S2",MID('📅 Calendrier'!$D10,SEARCH("séance",'📅 Calendrier'!$D10)+7,2),"") -> 4 | J7: =IF(LEFT('📅 Calendrier'!$D11,2)="S2",MID('📅 Calendrier'!$D11,SEARCH("séance",'📅 Calendrier'!$D11)+7,2),"") | K7: =IF(LEFT('📅 Calendrier'!$D13,2)="S2",MID('📅 Calendrier'!$D13,SEARCH("séance",'📅 Calendrier'!$D13)+7,2),"") | L7: =IF(LEFT('📅 Calendrier'!$D14,2)="S2",MID('📅 Calendrier'!$D14,SEARCH("séance",'📅 Calendrier'!$D14)+7,2),"") | M7: =IF(LEFT('📅 Calendrier'!$D15,2)="S2",MID('📅 Calendrier'!$D15,SEARCH("séance",'📅 Calendrier'!$D15)+7,2),"") | N7: =IF(LEFT('📅 Calendrier'!$D16,2)="S2",MID('📅 Calendrier'!$D16,SEARCH("séance",'📅 Calendrier'!$D16)+7,2),"") | O7: =IF(LEFT('📅 Calendrier'!$D17,2)="S2",MID('📅 Calendrier'!$D17,SEARCH("séance",'📅 Calendrier'!$D17)+7,2),"") | P7: =IF(LEFT('📅 Calendrier'!$D18,2)="S2",MID('📅 Calendrier'!$D18,SEARCH("séance",'📅 Calendrier'!$D18)+7,2),"") | Q7: =IF(LEFT('📅 Calendrier'!$D19,2)="S2",MID('📅 Calendrier'!$D19,SEARCH("séance",'📅 Calendrier'!$D19)+7,2),"") | R7: =IF(LEFT('📅 Calendrier'!$D21,2)="S2",MID('📅 Calendrier'!$D21,SEARCH("séance",'📅 Calendrier'!$D21)+7,2),"") | S7: =IF(LEFT('📅 Calendrier'!$D22,2)="S2",MID('📅 Calendrier'!$D22,SEARCH("séance",'📅 Calendrier'!$D22)+7,2),"") | T7: =IF(LEFT('📅 Calendrier'!$D23,2)="S2",MID('📅 Calendrier'!$D23,SEARCH("séance",'📅 Calendrier'!$D23)+7,2),"") | U7: =IF(LEFT('📅 Calendrier'!$D24,2)="S2",MID('📅 Calendrier'!$D24,SEARCH("séance",'📅 Calendrier'!$D24)+7,2),"") | V7: =IF(LEFT('📅 Calendrier'!$D25,2)="S2",MID('📅 Calendrier'!$D25,SEARCH("séance",'📅 Calendrier'!$D25)+7,2),"") | W7: =IF(LEFT('📅 Calendrier'!$D27,2)="S2",MID('📅 Calendrier'!$D27,SEARCH("séance",'📅 Calendrier'!$D27)+7,2),"") | X7: =IF(LEFT('📅 Calendrier'!$D28,2)="S2",MID('📅 Calendrier'!$D28,SEARCH("séance",'📅 Calendrier'!$D28)+7,2),"") | Y7: =IF(LEFT('📅 Calendrier'!$D29,2)="S2",MID('📅 Calendrier'!$D29,SEARCH("séance",'📅 Calendrier'!$D29)+7,2),"") | Z7: =IF(LEFT('📅 Calendrier'!$D30,2)="S2",MID('📅 Calendrier'!$D30,SEARCH("séance",'📅 Calendrier'!$D30)+7,2),"") | AA7: =IF(LEFT('📅 Calendrier'!$D31,2)="S2",MID('📅 Calendrier'!$D31,SEARCH("séance",'📅 Calendrier'!$D31)+7,2),"") | AB7: =IF(LEFT('📅 Calendrier'!$D32,2)="S2",MID('📅 Calendrier'!$D32,SEARCH("séance",'📅 Calendrier'!$D32)+7,2),"") | AC7: =IF(LEFT('📅 Calendrier'!$D33,2)="S2",MID('📅 Calendrier'!$D33,SEARCH("séance",'📅 Calendrier'!$D33)+7,2),"") | AD7: =IF(LEFT('📅 Calendrier'!$D34,2)="S2",MID('📅 Calendrier'!$D34,SEARCH("séance",'📅 Calendrier'!$D34)+7,2),"") | AE7: =IF(LEFT('📅 Calendrier'!$D36,2)="S2",MID('📅 Calendrier'!$D36,SEARCH("séance",'📅 Calendrier'!$D36)+7,2),"") | AF7: =IF(LEFT('📅 Calendrier'!$D37,2)="S2",MID('📅 Calendrier'!$D37,SEARCH("séance",'📅 Calendrier'!$D37)+7,2),"") | AG7: =IF(LEFT('📅 Calendrier'!$D38,2)="S2",MID('📅 Calendrier'!$D38,SEARCH("séance",'📅 Calendrier'!$D38)+7,2),"") | AH7: =IF(LEFT('📅 Calendrier'!$D39,2)="S2",MID('📅 Calendrier'!$D39,SEARCH("séance",'📅 Calendrier'!$D39)+7,2),"") | AI7: =IF(LEFT('📅 Calendrier'!$D40,2)="S2",MID('📅 Calendrier'!$D40,SEARCH("séance",'📅 Calendrier'!$D40)+7,2),"") | AJ7: =IF(LEFT('📅 Calendrier'!$D41,2)="S2",MID('📅 Calendrier'!$D41,SEARCH("séance",'📅 Calendrier'!$D41)+7,2),"") | AK7: =IF(LEFT('📅 Calendrier'!$D42,2)="S2",MID('📅 Calendrier'!$D42,SEARCH("séance",'📅 Calendrier'!$D42)+7,2),"") | AL7: =IF(LEFT('📅 Calendrier'!$D43,2)="S2",MID('📅 Calendrier'!$D43,SEARCH("séance",'📅 Calendrier'!$D43)+7,2),"") | AM7: =IF(LEFT('📅 Calendrier'!$D44,2)="S2",MID('📅 Calendrier'!$D44,SEARCH("séance",'📅 Calendrier'!$D44)+7,2),"")
B8: S3 · Chaîne d'énergie | C8: =IF(LEFT('📅 Calendrier'!$D4,2)="S3",MID('📅 Calendrier'!$D4,SEARCH("séance",'📅 Calendrier'!$D4)+7,2),"") | D8: =IF(LEFT('📅 Calendrier'!$D5,2)="S3",MID('📅 Calendrier'!$D5,SEARCH("séance",'📅 Calendrier'!$D5)+7,2),"") | E8: =IF(LEFT('📅 Calendrier'!$D6,2)="S3",MID('📅 Calendrier'!$D6,SEARCH("séance",'📅 Calendrier'!$D6)+7,2),"") | F8: =IF(LEFT('📅 Calendrier'!$D7,2)="S3",MID('📅 Calendrier'!$D7,SEARCH("séance",'📅 Calendrier'!$D7)+7,2),"") | G8: =IF(LEFT('📅 Calendrier'!$D8,2)="S3",MID('📅 Calendrier'!$D8,SEARCH("séance",'📅 Calendrier'!$D8)+7,2),"") | H8: =IF(LEFT('📅 Calendrier'!$D9,2)="S3",MID('📅 Calendrier'!$D9,SEARCH("séance",'📅 Calendrier'!$D9)+7,2),"") | I8: =IF(LEFT('📅 Calendrier'!$D10,2)="S3",MID('📅 Calendrier'!$D10,SEARCH("séance",'📅 Calendrier'!$D10)+7,2),"") | J8: =IF(LEFT('📅 Calendrier'!$D11,2)="S3",MID('📅 Calendrier'!$D11,SEARCH("séance",'📅 Calendrier'!$D11)+7,2),"") | K8: =IF(LEFT('📅 Calendrier'!$D13,2)="S3",MID('📅 Calendrier'!$D13,SEARCH("séance",'📅 Calendrier'!$D13)+7,2),"") -> 1 | L8: =IF(LEFT('📅 Calendrier'!$D14,2)="S3",MID('📅 Calendrier'!$D14,SEARCH("séance",'📅 Calendrier'!$D14)+7,2),"") -> 2 | M8: =IF(LEFT('📅 Calendrier'!$D15,2)="S3",MID('📅 Calendrier'!$D15,SEARCH("séance",'📅 Calendrier'!$D15)+7,2),"") -> 3 | N8: =IF(LEFT('📅 Calendrier'!$D16,2)="S3",MID('📅 Calendrier'!$D16,SEARCH("séance",'📅 Calendrier'!$D16)+7,2),"") -> 4 | O8: =IF(LEFT('📅 Calendrier'!$D17,2)="S3",MID('📅 Calendrier'!$D17,SEARCH("séance",'📅 Calendrier'!$D17)+7,2),"") | P8: =IF(LEFT('📅 Calendrier'!$D18,2)="S3",MID('📅 Calendrier'!$D18,SEARCH("séance",'📅 Calendrier'!$D18)+7,2),"") | Q8: =IF(LEFT('📅 Calendrier'!$D19,2)="S3",MID('📅 Calendrier'!$D19,SEARCH("séance",'📅 Calendrier'!$D19)+7,2),"") | R8: =IF(LEFT('📅 Calendrier'!$D21,2)="S3",MID('📅 Calendrier'!$D21,SEARCH("séance",'📅 Calendrier'!$D21)+7,2),"") | S8: =IF(LEFT('📅 Calendrier'!$D22,2)="S3",MID('📅 Calendrier'!$D22,SEARCH("séance",'📅 Calendrier'!$D22)+7,2),"") | T8: =IF(LEFT('📅 Calendrier'!$D23,2)="S3",MID('📅 Calendrier'!$D23,SEARCH("séance",'📅 Calendrier'!$D23)+7,2),"") | U8: =IF(LEFT('📅 Calendrier'!$D24,2)="S3",MID('📅 Calendrier'!$D24,SEARCH("séance",'📅 Calendrier'!$D24)+7,2),"") | V8: =IF(LEFT('📅 Calendrier'!$D25,2)="S3",MID('📅 Calendrier'!$D25,SEARCH("séance",'📅 Calendrier'!$D25)+7,2),"") | W8: =IF(LEFT('📅 Calendrier'!$D27,2)="S3",MID('📅 Calendrier'!$D27,SEARCH("séance",'📅 Calendrier'!$D27)+7,2),"") | X8: =IF(LEFT('📅 Calendrier'!$D28,2)="S3",MID('📅 Calendrier'!$D28,SEARCH("séance",'📅 Calendrier'!$D28)+7,2),"") | Y8: =IF(LEFT('📅 Calendrier'!$D29,2)="S3",MID('📅 Calendrier'!$D29,SEARCH("séance",'📅 Calendrier'!$D29)+7,2),"") | Z8: =IF(LEFT('📅 Calendrier'!$D30,2)="S3",MID('📅 Calendrier'!$D30,SEARCH("séance",'📅 Calendrier'!$D30)+7,2),"") | AA8: =IF(LEFT('📅 Calendrier'!$D31,2)="S3",MID('📅 Calendrier'!$D31,SEARCH("séance",'📅 Calendrier'!$D31)+7,2),"") | AB8: =IF(LEFT('📅 Calendrier'!$D32,2)="S3",MID('📅 Calendrier'!$D32,SEARCH("séance",'📅 Calendrier'!$D32)+7,2),"") | AC8: =IF(LEFT('📅 Calendrier'!$D33,2)="S3",MID('📅 Calendrier'!$D33,SEARCH("séance",'📅 Calendrier'!$D33)+7,2),"") | AD8: =IF(LEFT('📅 Calendrier'!$D34,2)="S3",MID('📅 Calendrier'!$D34,SEARCH("séance",'📅 Calendrier'!$D34)+7,2),"") | AE8: =IF(LEFT('📅 Calendrier'!$D36,2)="S3",MID('📅 Calendrier'!$D36,SEARCH("séance",'📅 Calendrier'!$D36)+7,2),"") | AF8: =IF(LEFT('📅 Calendrier'!$D37,2)="S3",MID('📅 Calendrier'!$D37,SEARCH("séance",'📅 Calendrier'!$D37)+7,2),"") | AG8: =IF(LEFT('📅 Calendrier'!$D38,2)="S3",MID('📅 Calendrier'!$D38,SEARCH("séance",'📅 Calendrier'!$D38)+7,2),"") | AH8: =IF(LEFT('📅 Calendrier'!$D39,2)="S3",MID('📅 Calendrier'!$D39,SEARCH("séance",'📅 Calendrier'!$D39)+7,2),"") | AI8: =IF(LEFT('📅 Calendrier'!$D40,2)="S3",MID('📅 Calendrier'!$D40,SEARCH("séance",'📅 Calendrier'!$D40)+7,2),"") | AJ8: =IF(LEFT('📅 Calendrier'!$D41,2)="S3",MID('📅 Calendrier'!$D41,SEARCH("séance",'📅 Calendrier'!$D41)+7,2),"") | AK8: =IF(LEFT('📅 Calendrier'!$D42,2)="S3",MID('📅 Calendrier'!$D42,SEARCH("séance",'📅 Calendrier'!$D42)+7,2),"") | AL8: =IF(LEFT('📅 Calendrier'!$D43,2)="S3",MID('📅 Calendrier'!$D43,SEARCH("séance",'📅 Calendrier'!$D43)+7,2),"") | AM8: =IF(LEFT('📅 Calendrier'!$D44,2)="S3",MID('📅 Calendrier'!$D44,SEARCH("séance",'📅 Calendrier'!$D44)+7,2),"")
B9: S4 · Lampadaire (1) : information & programmes | C9: =IF(LEFT('📅 Calendrier'!$D4,2)="S4",MID('📅 Calendrier'!$D4,SEARCH("séance",'📅 Calendrier'!$D4)+7,2),"") | D9: =IF(LEFT('📅 Calendrier'!$D5,2)="S4",MID('📅 Calendrier'!$D5,SEARCH("séance",'📅 Calendrier'!$D5)+7,2),"") | E9: =IF(LEFT('📅 Calendrier'!$D6,2)="S4",MID('📅 Calendrier'!$D6,SEARCH("séance",'📅 Calendrier'!$D6)+7,2),"") | F9: =IF(LEFT('📅 Calendrier'!$D7,2)="S4",MID('📅 Calendrier'!$D7,SEARCH("séance",'📅 Calendrier'!$D7)+7,2),"") | G9: =IF(LEFT('📅 Calendrier'!$D8,2)="S4",MID('📅 Calendrier'!$D8,SEARCH("séance",'📅 Calendrier'!$D8)+7,2),"") | H9: =IF(LEFT('📅 Calendrier'!$D9,2)="S4",MID('📅 Calendrier'!$D9,SEARCH("séance",'📅 Calendrier'!$D9)+7,2),"") | I9: =IF(LEFT('📅 Calendrier'!$D10,2)="S4",MID('📅 Calendrier'!$D10,SEARCH("séance",'📅 Calendrier'!$D10)+7,2),"") | J9: =IF(LEFT('📅 Calendrier'!$D11,2)="S4",MID('📅 Calendrier'!$D11,SEARCH("séance",'📅 Calendrier'!$D11)+7,2),"") | K9: =IF(LEFT('📅 Calendrier'!$D13,2)="S4",MID('📅 Calendrier'!$D13,SEARCH("séance",'📅 Calendrier'!$D13)+7,2),"") | L9: =IF(LEFT('📅 Calendrier'!$D14,2)="S4",MID('📅 Calendrier'!$D14,SEARCH("séance",'📅 Calendrier'!$D14)+7,2),"") | M9: =IF(LEFT('📅 Calendrier'!$D15,2)="S4",MID('📅 Calendrier'!$D15,SEARCH("séance",'📅 Calendrier'!$D15)+7,2),"") | N9: =IF(LEFT('📅 Calendrier'!$D16,2)="S4",MID('📅 Calendrier'!$D16,SEARCH("séance",'📅 Calendrier'!$D16)+7,2),"") | O9: =IF(LEFT('📅 Calendrier'!$D17,2)="S4",MID('📅 Calendrier'!$D17,SEARCH("séance",'📅 Calendrier'!$D17)+7,2),"") -> 1 | P9: =IF(LEFT('📅 Calendrier'!$D18,2)="S4",MID('📅 Calendrier'!$D18,SEARCH("séance",'📅 Calendrier'!$D18)+7,2),"") -> 2 | Q9: =IF(LEFT('📅 Calendrier'!$D19,2)="S4",MID('📅 Calendrier'!$D19,SEARCH("séance",'📅 Calendrier'!$D19)+7,2),"") | R9: =IF(LEFT('📅 Calendrier'!$D21,2)="S4",MID('📅 Calendrier'!$D21,SEARCH("séance",'📅 Calendrier'!$D21)+7,2),"") -> 3 | S9: =IF(LEFT('📅 Calendrier'!$D22,2)="S4",MID('📅 Calendrier'!$D22,SEARCH("séance",'📅 Calendrier'!$D22)+7,2),"") -> 4 | T9: =IF(LEFT('📅 Calendrier'!$D23,2)="S4",MID('📅 Calendrier'!$D23,SEARCH("séance",'📅 Calendrier'!$D23)+7,2),"") -> 5 | U9: =IF(LEFT('📅 Calendrier'!$D24,2)="S4",MID('📅 Calendrier'!$D24,SEARCH("séance",'📅 Calendrier'!$D24)+7,2),"") | V9: =IF(LEFT('📅 Calendrier'!$D25,2)="S4",MID('📅 Calendrier'!$D25,SEARCH("séance",'📅 Calendrier'!$D25)+7,2),"") | W9: =IF(LEFT('📅 Calendrier'!$D27,2)="S4",MID('📅 Calendrier'!$D27,SEARCH("séance",'📅 Calendrier'!$D27)+7,2),"") | X9: =IF(LEFT('📅 Calendrier'!$D28,2)="S4",MID('📅 Calendrier'!$D28,SEARCH("séance",'📅 Calendrier'!$D28)+7,2),"") | Y9: =IF(LEFT('📅 Calendrier'!$D29,2)="S4",MID('📅 Calendrier'!$D29,SEARCH("séance",'📅 Calendrier'!$D29)+7,2),"") | Z9: =IF(LEFT('📅 Calendrier'!$D30,2)="S4",MID('📅 Calendrier'!$D30,SEARCH("séance",'📅 Calendrier'!$D30)+7,2),"") | AA9: =IF(LEFT('📅 Calendrier'!$D31,2)="S4",MID('📅 Calendrier'!$D31,SEARCH("séance",'📅 Calendrier'!$D31)+7,2),"") | AB9: =IF(LEFT('📅 Calendrier'!$D32,2)="S4",MID('📅 Calendrier'!$D32,SEARCH("séance",'📅 Calendrier'!$D32)+7,2),"") | AC9: =IF(LEFT('📅 Calendrier'!$D33,2)="S4",MID('📅 Calendrier'!$D33,SEARCH("séance",'📅 Calendrier'!$D33)+7,2),"") | AD9: =IF(LEFT('📅 Calendrier'!$D34,2)="S4",MID('📅 Calendrier'!$D34,SEARCH("séance",'📅 Calendrier'!$D34)+7,2),"") | AE9: =IF(LEFT('📅 Calendrier'!$D36,2)="S4",MID('📅 Calendrier'!$D36,SEARCH("séance",'📅 Calendrier'!$D36)+7,2),"") | AF9: =IF(LEFT('📅 Calendrier'!$D37,2)="S4",MID('📅 Calendrier'!$D37,SEARCH("séance",'📅 Calendrier'!$D37)+7,2),"") | AG9: =IF(LEFT('📅 Calendrier'!$D38,2)="S4",MID('📅 Calendrier'!$D38,SEARCH("séance",'📅 Calendrier'!$D38)+7,2),"") | AH9: =IF(LEFT('📅 Calendrier'!$D39,2)="S4",MID('📅 Calendrier'!$D39,SEARCH("séance",'📅 Calendrier'!$D39)+7,2),"") | AI9: =IF(LEFT('📅 Calendrier'!$D40,2)="S4",MID('📅 Calendrier'!$D40,SEARCH("séance",'📅 Calendrier'!$D40)+7,2),"") | AJ9: =IF(LEFT('📅 Calendrier'!$D41,2)="S4",MID('📅 Calendrier'!$D41,SEARCH("séance",'📅 Calendrier'!$D41)+7,2),"") | AK9: =IF(LEFT('📅 Calendrier'!$D42,2)="S4",MID('📅 Calendrier'!$D42,SEARCH("séance",'📅 Calendrier'!$D42)+7,2),"") | AL9: =IF(LEFT('📅 Calendrier'!$D43,2)="S4",MID('📅 Calendrier'!$D43,SEARCH("séance",'📅 Calendrier'!$D43)+7,2),"") | AM9: =IF(LEFT('📅 Calendrier'!$D44,2)="S4",MID('📅 Calendrier'!$D44,SEARCH("séance",'📅 Calendrier'!$D44)+7,2),"")
B10: S5 · Lampadaire (2) : réseau local | C10: =IF(LEFT('📅 Calendrier'!$D4,2)="S5",MID('📅 Calendrier'!$D4,SEARCH("séance",'📅 Calendrier'!$D4)+7,2),"") | D10: =IF(LEFT('📅 Calendrier'!$D5,2)="S5",MID('📅 Calendrier'!$D5,SEARCH("séance",'📅 Calendrier'!$D5)+7,2),"") | E10: =IF(LEFT('📅 Calendrier'!$D6,2)="S5",MID('📅 Calendrier'!$D6,SEARCH("séance",'📅 Calendrier'!$D6)+7,2),"") | F10: =IF(LEFT('📅 Calendrier'!$D7,2)="S5",MID('📅 Calendrier'!$D7,SEARCH("séance",'📅 Calendrier'!$D7)+7,2),"") | G10: =IF(LEFT('📅 Calendrier'!$D8,2)="S5",MID('📅 Calendrier'!$D8,SEARCH("séance",'📅 Calendrier'!$D8)+7,2),"") | H10: =IF(LEFT('📅 Calendrier'!$D9,2)="S5",MID('📅 Calendrier'!$D9,SEARCH("séance",'📅 Calendrier'!$D9)+7,2),"") | I10: =IF(LEFT('📅 Calendrier'!$D10,2)="S5",MID('📅 Calendrier'!$D10,SEARCH("séance",'📅 Calendrier'!$D10)+7,2),"") | J10: =IF(LEFT('📅 Calendrier'!$D11,2)="S5",MID('📅 Calendrier'!$D11,SEARCH("séance",'📅 Calendrier'!$D11)+7,2),"") | K10: =IF(LEFT('📅 Calendrier'!$D13,2)="S5",MID('📅 Calendrier'!$D13,SEARCH("séance",'📅 Calendrier'!$D13)+7,2),"") | L10: =IF(LEFT('📅 Calendrier'!$D14,2)="S5",MID('📅 Calendrier'!$D14,SEARCH("séance",'📅 Calendrier'!$D14)+7,2),"") | M10: =IF(LEFT('📅 Calendrier'!$D15,2)="S5",MID('📅 Calendrier'!$D15,SEARCH("séance",'📅 Calendrier'!$D15)+7,2),"") | N10: =IF(LEFT('📅 Calendrier'!$D16,2)="S5",MID('📅 Calendrier'!$D16,SEARCH("séance",'📅 Calendrier'!$D16)+7,2),"") | O10: =IF(LEFT('📅 Calendrier'!$D17,2)="S5",MID('📅 Calendrier'!$D17,SEARCH("séance",'📅 Calendrier'!$D17)+7,2),"") | P10: =IF(LEFT('📅 Calendrier'!$D18,2)="S5",MID('📅 Calendrier'!$D18,SEARCH("séance",'📅 Calendrier'!$D18)+7,2),"") | Q10: =IF(LEFT('📅 Calendrier'!$D19,2)="S5",MID('📅 Calendrier'!$D19,SEARCH("séance",'📅 Calendrier'!$D19)+7,2),"") | R10: =IF(LEFT('📅 Calendrier'!$D21,2)="S5",MID('📅 Calendrier'!$D21,SEARCH("séance",'📅 Calendrier'!$D21)+7,2),"") | S10: =IF(LEFT('📅 Calendrier'!$D22,2)="S5",MID('📅 Calendrier'!$D22,SEARCH("séance",'📅 Calendrier'!$D22)+7,2),"") | T10: =IF(LEFT('📅 Calendrier'!$D23,2)="S5",MID('📅 Calendrier'!$D23,SEARCH("séance",'📅 Calendrier'!$D23)+7,2),"") | U10: =IF(LEFT('📅 Calendrier'!$D24,2)="S5",MID('📅 Calendrier'!$D24,SEARCH("séance",'📅 Calendrier'!$D24)+7,2),"") -> 1 | V10: =IF(LEFT('📅 Calendrier'!$D25,2)="S5",MID('📅 Calendrier'!$D25,SEARCH("séance",'📅 Calendrier'!$D25)+7,2),"") | W10: =IF(LEFT('📅 Calendrier'!$D27,2)="S5",MID('📅 Calendrier'!$D27,SEARCH("séance",'📅 Calendrier'!$D27)+7,2),"") -> 2 | X10: =IF(LEFT('📅 Calendrier'!$D28,2)="S5",MID('📅 Calendrier'!$D28,SEARCH("séance",'📅 Calendrier'!$D28)+7,2),"") -> 3 | Y10: =IF(LEFT('📅 Calendrier'!$D29,2)="S5",MID('📅 Calendrier'!$D29,SEARCH("séance",'📅 Calendrier'!$D29)+7,2),"") | Z10: =IF(LEFT('📅 Calendrier'!$D30,2)="S5",MID('📅 Calendrier'!$D30,SEARCH("séance",'📅 Calendrier'!$D30)+7,2),"") | AA10: =IF(LEFT('📅 Calendrier'!$D31,2)="S5",MID('📅 Calendrier'!$D31,SEARCH("séance",'📅 Calendrier'!$D31)+7,2),"") | AB10: =IF(LEFT('📅 Calendrier'!$D32,2)="S5",MID('📅 Calendrier'!$D32,SEARCH("séance",'📅 Calendrier'!$D32)+7,2),"") | AC10: =IF(LEFT('📅 Calendrier'!$D33,2)="S5",MID('📅 Calendrier'!$D33,SEARCH("séance",'📅 Calendrier'!$D33)+7,2),"") | AD10: =IF(LEFT('📅 Calendrier'!$D34,2)="S5",MID('📅 Calendrier'!$D34,SEARCH("séance",'📅 Calendrier'!$D34)+7,2),"") | AE10: =IF(LEFT('📅 Calendrier'!$D36,2)="S5",MID('📅 Calendrier'!$D36,SEARCH("séance",'📅 Calendrier'!$D36)+7,2),"") | AF10: =IF(LEFT('📅 Calendrier'!$D37,2)="S5",MID('📅 Calendrier'!$D37,SEARCH("séance",'📅 Calendrier'!$D37)+7,2),"") | AG10: =IF(LEFT('📅 Calendrier'!$D38,2)="S5",MID('📅 Calendrier'!$D38,SEARCH("séance",'📅 Calendrier'!$D38)+7,2),"") | AH10: =IF(LEFT('📅 Calendrier'!$D39,2)="S5",MID('📅 Calendrier'!$D39,SEARCH("séance",'📅 Calendrier'!$D39)+7,2),"") | AI10: =IF(LEFT('📅 Calendrier'!$D40,2)="S5",MID('📅 Calendrier'!$D40,SEARCH("séance",'📅 Calendrier'!$D40)+7,2),"") | AJ10: =IF(LEFT('📅 Calendrier'!$D41,2)="S5",MID('📅 Calendrier'!$D41,SEARCH("séance",'📅 Calendrier'!$D41)+7,2),"") | AK10: =IF(LEFT('📅 Calendrier'!$D42,2)="S5",MID('📅 Calendrier'!$D42,SEARCH("séance",'📅 Calendrier'!$D42)+7,2),"") | AL10: =IF(LEFT('📅 Calendrier'!$D43,2)="S5",MID('📅 Calendrier'!$D43,SEARCH("séance",'📅 Calendrier'!$D43)+7,2),"") | AM10: =IF(LEFT('📅 Calendrier'!$D44,2)="S5",MID('📅 Calendrier'!$D44,SEARCH("séance",'📅 Calendrier'!$D44)+7,2),"")
B11: S6 · SOS panne | C11: =IF(LEFT('📅 Calendrier'!$D4,2)="S6",MID('📅 Calendrier'!$D4,SEARCH("séance",'📅 Calendrier'!$D4)+7,2),"") | D11: =IF(LEFT('📅 Calendrier'!$D5,2)="S6",MID('📅 Calendrier'!$D5,SEARCH("séance",'📅 Calendrier'!$D5)+7,2),"") | E11: =IF(LEFT('📅 Calendrier'!$D6,2)="S6",MID('📅 Calendrier'!$D6,SEARCH("séance",'📅 Calendrier'!$D6)+7,2),"") | F11: =IF(LEFT('📅 Calendrier'!$D7,2)="S6",MID('📅 Calendrier'!$D7,SEARCH("séance",'📅 Calendrier'!$D7)+7,2),"") | G11: =IF(LEFT('📅 Calendrier'!$D8,2)="S6",MID('📅 Calendrier'!$D8,SEARCH("séance",'📅 Calendrier'!$D8)+7,2),"") | H11: =IF(LEFT('📅 Calendrier'!$D9,2)="S6",MID('📅 Calendrier'!$D9,SEARCH("séance",'📅 Calendrier'!$D9)+7,2),"") | I11: =IF(LEFT('📅 Calendrier'!$D10,2)="S6",MID('📅 Calendrier'!$D10,SEARCH("séance",'📅 Calendrier'!$D10)+7,2),"") | J11: =IF(LEFT('📅 Calendrier'!$D11,2)="S6",MID('📅 Calendrier'!$D11,SEARCH("séance",'📅 Calendrier'!$D11)+7,2),"") | K11: =IF(LEFT('📅 Calendrier'!$D13,2)="S6",MID('📅 Calendrier'!$D13,SEARCH("séance",'📅 Calendrier'!$D13)+7,2),"") | L11: =IF(LEFT('📅 Calendrier'!$D14,2)="S6",MID('📅 Calendrier'!$D14,SEARCH("séance",'📅 Calendrier'!$D14)+7,2),"") | M11: =IF(LEFT('📅 Calendrier'!$D15,2)="S6",MID('📅 Calendrier'!$D15,SEARCH("séance",'📅 Calendrier'!$D15)+7,2),"") | N11: =IF(LEFT('📅 Calendrier'!$D16,2)="S6",MID('📅 Calendrier'!$D16,SEARCH("séance",'📅 Calendrier'!$D16)+7,2),"") | O11: =IF(LEFT('📅 Calendrier'!$D17,2)="S6",MID('📅 Calendrier'!$D17,SEARCH("séance",'📅 Calendrier'!$D17)+7,2),"") | P11: =IF(LEFT('📅 Calendrier'!$D18,2)="S6",MID('📅 Calendrier'!$D18,SEARCH("séance",'📅 Calendrier'!$D18)+7,2),"") | Q11: =IF(LEFT('📅 Calendrier'!$D19,2)="S6",MID('📅 Calendrier'!$D19,SEARCH("séance",'📅 Calendrier'!$D19)+7,2),"") | R11: =IF(LEFT('📅 Calendrier'!$D21,2)="S6",MID('📅 Calendrier'!$D21,SEARCH("séance",'📅 Calendrier'!$D21)+7,2),"") | S11: =IF(LEFT('📅 Calendrier'!$D22,2)="S6",MID('📅 Calendrier'!$D22,SEARCH("séance",'📅 Calendrier'!$D22)+7,2),"") | T11: =IF(LEFT('📅 Calendrier'!$D23,2)="S6",MID('📅 Calendrier'!$D23,SEARCH("séance",'📅 Calendrier'!$D23)+7,2),"") | U11: =IF(LEFT('📅 Calendrier'!$D24,2)="S6",MID('📅 Calendrier'!$D24,SEARCH("séance",'📅 Calendrier'!$D24)+7,2),"") | V11: =IF(LEFT('📅 Calendrier'!$D25,2)="S6",MID('📅 Calendrier'!$D25,SEARCH("séance",'📅 Calendrier'!$D25)+7,2),"") | W11: =IF(LEFT('📅 Calendrier'!$D27,2)="S6",MID('📅 Calendrier'!$D27,SEARCH("séance",'📅 Calendrier'!$D27)+7,2),"") | X11: =IF(LEFT('📅 Calendrier'!$D28,2)="S6",MID('📅 Calendrier'!$D28,SEARCH("séance",'📅 Calendrier'!$D28)+7,2),"") | Y11: =IF(LEFT('📅 Calendrier'!$D29,2)="S6",MID('📅 Calendrier'!$D29,SEARCH("séance",'📅 Calendrier'!$D29)+7,2),"") -> 1 | Z11: =IF(LEFT('📅 Calendrier'!$D30,2)="S6",MID('📅 Calendrier'!$D30,SEARCH("séance",'📅 Calendrier'!$D30)+7,2),"") -> 2 | AA11: =IF(LEFT('📅 Calendrier'!$D31,2)="S6",MID('📅 Calendrier'!$D31,SEARCH("séance",'📅 Calendrier'!$D31)+7,2),"") -> 3 | AB11: =IF(LEFT('📅 Calendrier'!$D32,2)="S6",MID('📅 Calendrier'!$D32,SEARCH("séance",'📅 Calendrier'!$D32)+7,2),"") -> 4 | AC11: =IF(LEFT('📅 Calendrier'!$D33,2)="S6",MID('📅 Calendrier'!$D33,SEARCH("séance",'📅 Calendrier'!$D33)+7,2),"") | AD11: =IF(LEFT('📅 Calendrier'!$D34,2)="S6",MID('📅 Calendrier'!$D34,SEARCH("séance",'📅 Calendrier'!$D34)+7,2),"") | AE11: =IF(LEFT('📅 Calendrier'!$D36,2)="S6",MID('📅 Calendrier'!$D36,SEARCH("séance",'📅 Calendrier'!$D36)+7,2),"") | AF11: =IF(LEFT('📅 Calendrier'!$D37,2)="S6",MID('📅 Calendrier'!$D37,SEARCH("séance",'📅 Calendrier'!$D37)+7,2),"") | AG11: =IF(LEFT('📅 Calendrier'!$D38,2)="S6",MID('📅 Calendrier'!$D38,SEARCH("séance",'📅 Calendrier'!$D38)+7,2),"") | AH11: =IF(LEFT('📅 Calendrier'!$D39,2)="S6",MID('📅 Calendrier'!$D39,SEARCH("séance",'📅 Calendrier'!$D39)+7,2),"") | AI11: =IF(LEFT('📅 Calendrier'!$D40,2)="S6",MID('📅 Calendrier'!$D40,SEARCH("séance",'📅 Calendrier'!$D40)+7,2),"") | AJ11: =IF(LEFT('📅 Calendrier'!$D41,2)="S6",MID('📅 Calendrier'!$D41,SEARCH("séance",'📅 Calendrier'!$D41)+7,2),"") | AK11: =IF(LEFT('📅 Calendrier'!$D42,2)="S6",MID('📅 Calendrier'!$D42,SEARCH("séance",'📅 Calendrier'!$D42)+7,2),"") | AL11: =IF(LEFT('📅 Calendrier'!$D43,2)="S6",MID('📅 Calendrier'!$D43,SEARCH("séance",'📅 Calendrier'!$D43)+7,2),"") | AM11: =IF(LEFT('📅 Calendrier'!$D44,2)="S6",MID('📅 Calendrier'!$D44,SEARCH("séance",'📅 Calendrier'!$D44)+7,2),"")
B12: S7 · Mini-projet | C12: =IF(LEFT('📅 Calendrier'!$D4,2)="S7",MID('📅 Calendrier'!$D4,SEARCH("séance",'📅 Calendrier'!$D4)+7,2),"") | D12: =IF(LEFT('📅 Calendrier'!$D5,2)="S7",MID('📅 Calendrier'!$D5,SEARCH("séance",'📅 Calendrier'!$D5)+7,2),"") | E12: =IF(LEFT('📅 Calendrier'!$D6,2)="S7",MID('📅 Calendrier'!$D6,SEARCH("séance",'📅 Calendrier'!$D6)+7,2),"") | F12: =IF(LEFT('📅 Calendrier'!$D7,2)="S7",MID('📅 Calendrier'!$D7,SEARCH("séance",'📅 Calendrier'!$D7)+7,2),"") | G12: =IF(LEFT('📅 Calendrier'!$D8,2)="S7",MID('📅 Calendrier'!$D8,SEARCH("séance",'📅 Calendrier'!$D8)+7,2),"") | H12: =IF(LEFT('📅 Calendrier'!$D9,2)="S7",MID('📅 Calendrier'!$D9,SEARCH("séance",'📅 Calendrier'!$D9)+7,2),"") | I12: =IF(LEFT('📅 Calendrier'!$D10,2)="S7",MID('📅 Calendrier'!$D10,SEARCH("séance",'📅 Calendrier'!$D10)+7,2),"") | J12: =IF(LEFT('📅 Calendrier'!$D11,2)="S7",MID('📅 Calendrier'!$D11,SEARCH("séance",'📅 Calendrier'!$D11)+7,2),"") | K12: =IF(LEFT('📅 Calendrier'!$D13,2)="S7",MID('📅 Calendrier'!$D13,SEARCH("séance",'📅 Calendrier'!$D13)+7,2),"") | L12: =IF(LEFT('📅 Calendrier'!$D14,2)="S7",MID('📅 Calendrier'!$D14,SEARCH("séance",'📅 Calendrier'!$D14)+7,2),"") | M12: =IF(LEFT('📅 Calendrier'!$D15,2)="S7",MID('📅 Calendrier'!$D15,SEARCH("séance",'📅 Calendrier'!$D15)+7,2),"") | N12: =IF(LEFT('📅 Calendrier'!$D16,2)="S7",MID('📅 Calendrier'!$D16,SEARCH("séance",'📅 Calendrier'!$D16)+7,2),"") | O12: =IF(LEFT('📅 Calendrier'!$D17,2)="S7",MID('📅 Calendrier'!$D17,SEARCH("séance",'📅 Calendrier'!$D17)+7,2),"") | P12: =IF(LEFT('📅 Calendrier'!$D18,2)="S7",MID('📅 Calendrier'!$D18,SEARCH("séance",'📅 Calendrier'!$D18)+7,2),"") | Q12: =IF(LEFT('📅 Calendrier'!$D19,2)="S7",MID('📅 Calendrier'!$D19,SEARCH("séance",'📅 Calendrier'!$D19)+7,2),"") | R12: =IF(LEFT('📅 Calendrier'!$D21,2)="S7",MID('📅 Calendrier'!$D21,SEARCH("séance",'📅 Calendrier'!$D21)+7,2),"") | S12: =IF(LEFT('📅 Calendrier'!$D22,2)="S7",MID('📅 Calendrier'!$D22,SEARCH("séance",'📅 Calendrier'!$D22)+7,2),"") | T12: =IF(LEFT('📅 Calendrier'!$D23,2)="S7",MID('📅 Calendrier'!$D23,SEARCH("séance",'📅 Calendrier'!$D23)+7,2),"") | U12: =IF(LEFT('📅 Calendrier'!$D24,2)="S7",MID('📅 Calendrier'!$D24,SEARCH("séance",'📅 Calendrier'!$D24)+7,2),"") | V12: =IF(LEFT('📅 Calendrier'!$D25,2)="S7",MID('📅 Calendrier'!$D25,SEARCH("séance",'📅 Calendrier'!$D25)+7,2),"") | W12: =IF(LEFT('📅 Calendrier'!$D27,2)="S7",MID('📅 Calendrier'!$D27,SEARCH("séance",'📅 Calendrier'!$D27)+7,2),"") | X12: =IF(LEFT('📅 Calendrier'!$D28,2)="S7",MID('📅 Calendrier'!$D28,SEARCH("séance",'📅 Calendrier'!$D28)+7,2),"") | Y12: =IF(LEFT('📅 Calendrier'!$D29,2)="S7",MID('📅 Calendrier'!$D29,SEARCH("séance",'📅 Calendrier'!$D29)+7,2),"") | Z12: =IF(LEFT('📅 Calendrier'!$D30,2)="S7",MID('📅 Calendrier'!$D30,SEARCH("séance",'📅 Calendrier'!$D30)+7,2),"") | AA12: =IF(LEFT('📅 Calendrier'!$D31,2)="S7",MID('📅 Calendrier'!$D31,SEARCH("séance",'📅 Calendrier'!$D31)+7,2),"") | AB12: =IF(LEFT('📅 Calendrier'!$D32,2)="S7",MID('📅 Calendrier'!$D32,SEARCH("séance",'📅 Calendrier'!$D32)+7,2),"") | AC12: =IF(LEFT('📅 Calendrier'!$D33,2)="S7",MID('📅 Calendrier'!$D33,SEARCH("séance",'📅 Calendrier'!$D33)+7,2),"") -> 1 | AD12: =IF(LEFT('📅 Calendrier'!$D34,2)="S7",MID('📅 Calendrier'!$D34,SEARCH("séance",'📅 Calendrier'!$D34)+7,2),"") | AE12: =IF(LEFT('📅 Calendrier'!$D36,2)="S7",MID('📅 Calendrier'!$D36,SEARCH("séance",'📅 Calendrier'!$D36)+7,2),"") -> 2 | AF12: =IF(LEFT('📅 Calendrier'!$D37,2)="S7",MID('📅 Calendrier'!$D37,SEARCH("séance",'📅 Calendrier'!$D37)+7,2),"") -> 3 | AG12: =IF(LEFT('📅 Calendrier'!$D38,2)="S7",MID('📅 Calendrier'!$D38,SEARCH("séance",'📅 Calendrier'!$D38)+7,2),"") -> 4 | AH12: =IF(LEFT('📅 Calendrier'!$D39,2)="S7",MID('📅 Calendrier'!$D39,SEARCH("séance",'📅 Calendrier'!$D39)+7,2),"") -> 5 | AI12: =IF(LEFT('📅 Calendrier'!$D40,2)="S7",MID('📅 Calendrier'!$D40,SEARCH("séance",'📅 Calendrier'!$D40)+7,2),"") -> 6 | AJ12: =IF(LEFT('📅 Calendrier'!$D41,2)="S7",MID('📅 Calendrier'!$D41,SEARCH("séance",'📅 Calendrier'!$D41)+7,2),"") | AK12: =IF(LEFT('📅 Calendrier'!$D42,2)="S7",MID('📅 Calendrier'!$D42,SEARCH("séance",'📅 Calendrier'!$D42)+7,2),"") | AL12: =IF(LEFT('📅 Calendrier'!$D43,2)="S7",MID('📅 Calendrier'!$D43,SEARCH("séance",'📅 Calendrier'!$D43)+7,2),"") | AM12: =IF(LEFT('📅 Calendrier'!$D44,2)="S7",MID('📅 Calendrier'!$D44,SEARCH("séance",'📅 Calendrier'!$D44)+7,2),"")
B13: ⏳ Tampons (rattrapage) | C13: =IF(LEFT('📅 Calendrier'!$D4,1)="⏳","⏳","") | D13: =IF(LEFT('📅 Calendrier'!$D5,1)="⏳","⏳","") | E13: =IF(LEFT('📅 Calendrier'!$D6,1)="⏳","⏳","") | F13: =IF(LEFT('📅 Calendrier'!$D7,1)="⏳","⏳","") | G13: =IF(LEFT('📅 Calendrier'!$D8,1)="⏳","⏳","") | H13: =IF(LEFT('📅 Calendrier'!$D9,1)="⏳","⏳","") | I13: =IF(LEFT('📅 Calendrier'!$D10,1)="⏳","⏳","") | J13: =IF(LEFT('📅 Calendrier'!$D11,1)="⏳","⏳","") -> ⏳ | K13: =IF(LEFT('📅 Calendrier'!$D13,1)="⏳","⏳","") | L13: =IF(LEFT('📅 Calendrier'!$D14,1)="⏳","⏳","") | M13: =IF(LEFT('📅 Calendrier'!$D15,1)="⏳","⏳","") | N13: =IF(LEFT('📅 Calendrier'!$D16,1)="⏳","⏳","") | O13: =IF(LEFT('📅 Calendrier'!$D17,1)="⏳","⏳","") | P13: =IF(LEFT('📅 Calendrier'!$D18,1)="⏳","⏳","") | Q13: =IF(LEFT('📅 Calendrier'!$D19,1)="⏳","⏳","") -> ⏳ | R13: =IF(LEFT('📅 Calendrier'!$D21,1)="⏳","⏳","") | S13: =IF(LEFT('📅 Calendrier'!$D22,1)="⏳","⏳","") | T13: =IF(LEFT('📅 Calendrier'!$D23,1)="⏳","⏳","") | U13: =IF(LEFT('📅 Calendrier'!$D24,1)="⏳","⏳","") | V13: =IF(LEFT('📅 Calendrier'!$D25,1)="⏳","⏳","") -> ⏳ | W13: =IF(LEFT('📅 Calendrier'!$D27,1)="⏳","⏳","") | X13: =IF(LEFT('📅 Calendrier'!$D28,1)="⏳","⏳","") | Y13: =IF(LEFT('📅 Calendrier'!$D29,1)="⏳","⏳","") | Z13: =IF(LEFT('📅 Calendrier'!$D30,1)="⏳","⏳","") | AA13: =IF(LEFT('📅 Calendrier'!$D31,1)="⏳","⏳","") | AB13: =IF(LEFT('📅 Calendrier'!$D32,1)="⏳","⏳","") | AC13: =IF(LEFT('📅 Calendrier'!$D33,1)="⏳","⏳","") | AD13: =IF(LEFT('📅 Calendrier'!$D34,1)="⏳","⏳","") -> ⏳ | AE13: =IF(LEFT('📅 Calendrier'!$D36,1)="⏳","⏳","") | AF13: =IF(LEFT('📅 Calendrier'!$D37,1)="⏳","⏳","") | AG13: =IF(LEFT('📅 Calendrier'!$D38,1)="⏳","⏳","") | AH13: =IF(LEFT('📅 Calendrier'!$D39,1)="⏳","⏳","") | AI13: =IF(LEFT('📅 Calendrier'!$D40,1)="⏳","⏳","") | AJ13: =IF(LEFT('📅 Calendrier'!$D41,1)="⏳","⏳","") -> ⏳ | AK13: =IF(LEFT('📅 Calendrier'!$D42,1)="⏳","⏳","") -> ⏳ | AL13: =IF(LEFT('📅 Calendrier'!$D43,1)="⏳","⏳","") -> ⏳ | AM13: =IF(LEFT('📅 Calendrier'!$D44,1)="⏳","⏳","") -> ⏳
B14: ⚠ Imprévus (saisis au Calendrier) | C14: =IF('📅 Calendrier'!$G4<>"","⚠","") | D14: =IF('📅 Calendrier'!$G5<>"","⚠","") | E14: =IF('📅 Calendrier'!$G6<>"","⚠","") | F14: =IF('📅 Calendrier'!$G7<>"","⚠","") | G14: =IF('📅 Calendrier'!$G8<>"","⚠","") | H14: =IF('📅 Calendrier'!$G9<>"","⚠","") | I14: =IF('📅 Calendrier'!$G10<>"","⚠","") | J14: =IF('📅 Calendrier'!$G11<>"","⚠","") | K14: =IF('📅 Calendrier'!$G13<>"","⚠","") | L14: =IF('📅 Calendrier'!$G14<>"","⚠","") | M14: =IF('📅 Calendrier'!$G15<>"","⚠","") | N14: =IF('📅 Calendrier'!$G16<>"","⚠","") | O14: =IF('📅 Calendrier'!$G17<>"","⚠","") | P14: =IF('📅 Calendrier'!$G18<>"","⚠","") | Q14: =IF('📅 Calendrier'!$G19<>"","⚠","") | R14: =IF('📅 Calendrier'!$G21<>"","⚠","") | S14: =IF('📅 Calendrier'!$G22<>"","⚠","") | T14: =IF('📅 Calendrier'!$G23<>"","⚠","") | U14: =IF('📅 Calendrier'!$G24<>"","⚠","") | V14: =IF('📅 Calendrier'!$G25<>"","⚠","") | W14: =IF('📅 Calendrier'!$G27<>"","⚠","") | X14: =IF('📅 Calendrier'!$G28<>"","⚠","") | Y14: =IF('📅 Calendrier'!$G29<>"","⚠","") | Z14: =IF('📅 Calendrier'!$G30<>"","⚠","") | AA14: =IF('📅 Calendrier'!$G31<>"","⚠","") | AB14: =IF('📅 Calendrier'!$G32<>"","⚠","") | AC14: =IF('📅 Calendrier'!$G33<>"","⚠","") | AD14: =IF('📅 Calendrier'!$G34<>"","⚠","") | AE14: =IF('📅 Calendrier'!$G36<>"","⚠","") | AF14: =IF('📅 Calendrier'!$G37<>"","⚠","") | AG14: =IF('📅 Calendrier'!$G38<>"","⚠","") | AH14: =IF('📅 Calendrier'!$G39<>"","⚠","") | AI14: =IF('📅 Calendrier'!$G40<>"","⚠","") | AJ14: =IF('📅 Calendrier'!$G41<>"","⚠","") | AK14: =IF('📅 Calendrier'!$G42<>"","⚠","") | AL14: =IF('📅 Calendrier'!$G43<>"","⚠","") | AM14: =IF('📅 Calendrier'!$G44<>"","⚠","")
B16: Une case = 1 semaine (1 séance de 1 h 30) ; le numéro = n° de séance dans la séquence. Pour insérer un imprévu : onglet 📅 Calendrier, colonne « ⚠ Imprévu ? », choisir dans le menu de la semaine concernée — la frise et la progression se recalculent immédiatement. Cliquer sur un titre de séquence ouvre son générateur.

Sheet 📚 Référentiel Cycle 4
A1: RÉFÉRENTIEL DE COMPÉTENCES — TECHNOLOGIE CYCLE 4
A2: 9 compétences × 3 niveaux (5e / 4e / 3e) — programme 2024 · vision complète du cycle pour situer la 5e
F3: ◀ Accueil
A4: Code | B4: Niveau | C4: Compétence / sous-compétence (intitulé officiel 2024) | D4: Thème | E4: Domaine(s) socle | F4: Évaluable
A5: C1 | B5: — | C5: Décrire les liens entre usages et évolutions technologiques des objets et des systèmes techniques | D5: Thème 1 : Les objets et les systèmes techniques : leurs usages et leurs interactions à découvrir et à analyser | E5: D2, D3, D4, D5 | F5: Oui
A6: 5e_C1.1 | B6: 5e | C6: Collecter, trier et analyser des données. | D6: Thème 1 | E6: D2, D4 | F6: Oui
A7: 5e_C1.2 | B7: 5e | C7: Comparer des principes techniques pour une même fonction technique. | D7: Thème 1 | E7: D2, D4 | F7: Oui
A8: 5e_C1.3 | B8: 5e | C8: Décrire le rôle des systèmes d’information dans le partage d’information. | D8: Thème 1 | E8: D2, D5 | F8: Oui
A9: 5e_C1.4 | B9: 5e | C9: Recenser des données, les identifier, les classer, les représenter, les stocker, les retrouver dans une arborescence. | D9: Thème 1 | E9: D2 | F9: Oui
A10: 5e_C1.5 | B10: 5e | C10: Identifier des règles permettant de sécuriser un environnement numérique (bases de la cybersécurité) et des règles de respect de la propriété intellectuelle. | D10: Thème 1 | E10: D3 | F10: Oui
A11: 5e_C1.6 | B11: 5e | C11: Appréhender la responsabilité de chacun dans les dérives (cyberviolence, atteinte à la vie privée, aux données personnelles, usurpation d’identité). | D11: Thème 1 | E11: D3 | F11: Oui
A12: 4e_C1.1 | B12: 4e | C12: Mettre en relation les OST avec leurs usages. | D12: Thème 1 | E12: D4, D5 | F12: Oui
A13: 4e_C1.2 | B13: 4e | C13: Identifier les avantages et les inconvénients associés aux évolutions technologiques et informatiques. | D13: Thème 1 | E13: D3, D4, D5 | F13: Oui
A14: 4e_C1.3 | B14: 4e | C14: Justifier l’évolution d’un OST pour répondre à l’évolution des besoins. | D14: Thème 1 | E14: D3, D4, D5 | F14: Oui
A15: 4e_C1.4 | B15: 4e | C15: Identifier et appliquer les règles pour un usage raisonné des objets communicants et des environnements numériques (propriété intellectuelle, identité numérique, témoins de connexion, géolocalisation). | D15: Thème 1 | E15: D1.3, D2, D3, D4 | F15: Oui
... A127: 3e_C9.2 | B127: 3e | C127: Réaliser et mettre au point un programme commandant un système réel incluant une interaction entre un humain et une machine. | D127: Thème 3 | E127: D1.3, D2, D4 | F127: Oui
A129: 114 sous-compétences listées · Source : BO n°9 du 29/02/2024 (arrêté du 22/01/2024) · codes Nathan (éd. 2024).

Sheet 📗 Référentiel 5e
A1: RÉFÉRENTIEL DE COMPÉTENCES — TECHNOLOGIE 5e
A2: Les compétences parentes C1 → C9 et leurs déclinaisons du niveau 5e — celles travaillées dans ce classeur
F3: ◀ Accueil
A4: Code | B4: Niveau | C4: Compétence / sous-compétence (intitulé officiel 2024) | D4: Thème | E4: Domaine(s) socle | F4: Évaluable
A5: C1 | B5: — | C5: Décrire les liens entre usages et évolutions technologiques des objets et des systèmes techniques | D5: Thème 1 : Les objets et les systèmes techniques : leurs usages et leurs interactions à découvrir et à analyser | E5: D2, D3, D4, D5 | F5: Oui
A6: 5e_C1.1 | B6: 5e | C6: Collecter, trier et analyser des données. | D6: Thème 1 | E6: D2, D4 | F6: Oui
A7: 5e_C1.2 | B7: 5e | C7: Comparer des principes techniques pour une même fonction technique. | D7: Thème 1 | E7: D2, D4 | F7: Oui
A8: 5e_C1.3 | B8: 5e | C8: Décrire le rôle des systèmes d’information dans le partage d’information. | D8: Thème 1 | E8: D2, D5 | F8: Oui
A9: 5e_C1.4 | B9: 5e | C9: Recenser des données, les identifier, les classer, les représenter, les stocker, les retrouver dans une arborescence. | D9: Thème 1 | E9: D2 | F9: Oui
A10: 5e_C1.5 | B10: 5e | C10: Identifier des règles permettant de sécuriser un environnement numérique (bases de la cybersécurité) et des règles de respect de la propriété intellectuelle. | D10: Thème 1 | E10: D3 | F10: Oui
A11: 5e_C1.6 | B11: 5e | C11: Appréhender la responsabilité de chacun dans les dérives (cyberviolence, atteinte à la vie privée, aux données personnelles, usurpation d’identité). | D11: Thème 1 | E11: D3 | F11: Oui
A12: C2 | B12: — | C12: Décrire les interactions entre un objet ou un système technique, son environnement et les utilisateurs | D12: Thème 1 | E12: D4, D5 | F12: Oui
A13: 5e_C2.1 | B13: 5e | C13: Faire la liste des interacteurs extérieurs d’un OST. | D13: Thème 1 | E13: D4 | F13: Oui
A14: 5e_C2.2 | B14: 5e | C14: Repérer et expliquer les choix de conception dans les domaines de l’ergonomie et de la sécurité ou en lien avec des objectifs de développement durable. | D14: Thème 1 | E14: D4, D5 | F14: Oui
A15: C3 | B15: — | C15: Caractériser et choisir un objet ou un système technique selon différents critères | D15: Thème 1 | E15: D1.3, D2, D3, D4, D5 | F15: Oui
... A51: 5e_C9.3 | B51: 5e | C51: Réaliser et mettre au point un programme simple commandant un OST. | D51: Thème 3 | E51: D1.3, D2, D4 | F51: Oui
A53: 38 sous-compétences listées · Source : BO n°9 du 29/02/2024 (arrêté du 22/01/2024) · codes Nathan (éd. 2024).

Sheet 🧭 Progression
A1: PROGRESSION ANNUELLE 5e — 2026-2027 · 7 séquences · base : Référentiel 2024 (onglet Progression 5e)
K2: ◀ Accueil
A3: N° | B3: Période | C3: Titre (support actualisé) | D3: Problématique | E3: Thème | F3: Codes 2024 | G3: Séances | H3: Répartition 🏫 / 🏠 / 🔁 | I3: Ressources en ligne (dépôt) | J3: Cahier Nathan 5e (repères) | K3: IA responsable | L3: Début (AUTO) | M3: Fin (AUTO)
A4: 1 | B4: P1 | C4: Bien démarrer : mon environnement numérique au collège | D4: Comment organiser et sécuriser mon espace de travail numérique ? | E4: Thème 1 | F4: 5e_C1.4, C1.5, C1.6 | G4: 3 | H4: Séance 1 🏫 (prise en main ENT) · 2 🔁 (arborescence : exercice en ligne à la maison) · 3 🏫 (mots de passe + bilan) | I4: 🔜 À produire (Thème 1) | J4: Prob. 3 p.23-30 (vie privée) · Point méthode 3 p.88 (arborescence) · Vers Pix D4 p.119-124 | K4: IA Thème 1 | L4: =IFERROR(INDEX('📅 Calendrier'!$A$4:$A$44,MATCH("S1 · séance 1",'📅 Calendrier'!$D$4:$D$44,0))&" ("&INDEX('📅 Calendrier'!$B$4:$B$44,MATCH("S1 · séance 1",'📅 Calendrier'!$D$4:$D$44,0))&")","⚠ hors année !") -> S01 (31/08/2026) | M4: =IFERROR(INDEX('📅 Calendrier'!$A$4:$A$44,MATCH("S1 · séance 3",'📅 Calendrier'!$D$4:$D$44,0))&" ("&INDEX('📅 Calendrier'!$B$4:$B$44,MATCH("S1 · séance 3",'📅 Calendrier'!$D$4:$D$44,0))&")","⚠ hors année !") -> S03 (14/09/2026)
A5: 2 | B5: P1 | C5: Comparer pour choisir : quel objet répond le mieux au besoin ? | D5: Comment choisir le meilleur objet technique parmi plusieurs ? | E5: Thème 1 | F5: 5e_C1.1, C1.2, C1.3, C3.1, C3.3 | G5: 4 | H5: Séances 1-2 🏫 (objets réels, tableau comparatif) · 3 🔁 (recherche doc maison) · 4 🏫 (choix argumenté + éval.) | I5: 🔜 À produire (Thème 1) | J5: Prob. 1 p.7-14 (évolution des objets) · Prob. 2 p.15-22 (choisir le bon vélo électrique) | K5: IA Thème 1 | L5: =IFERROR(INDEX('📅 Calendrier'!$A$4:$A$44,MATCH("S2 · séance 1",'📅 Calendrier'!$D$4:$D$44,0))&" ("&INDEX('📅 Calendrier'!$B$4:$B$44,MATCH("S2 · séance 1",'📅 Calendrier'!$D$4:$D$44,0))&")","⚠ hors année !") -> S04 (21/09/2026) | M5: =IFERROR(INDEX('📅 Calendrier'!$A$4:$A$44,MATCH("S2 · séance 4",'📅 Calendrier'!$D$4:$D$44,0))&" ("&INDEX('📅 Calendrier'!$B$4:$B$44,MATCH("S2 · séance 4",'📅 Calendrier'!$D$4:$D$44,0))&")","⚠ hors année !") -> S07 (12/10/2026)
A6: 3 | B6: P2 | C6: La chaîne d'énergie : comment un objet transforme-t-il l'énergie ? | D6: Comment l'énergie circule-t-elle dans un objet technique ? | E6: Thème 1 | F6: 5e_C2.1, C2.2 (Th.1) + 5e_C4.1, C4.2, C4.3 (Th.2) | G6: 4 | H6: Séances 1-2 🏫 (maquette moteur/LED) · 3 🔁 (séances 1-2 du lampadaire en ligne à la maison) · 4 🏫 (schéma-bloc + éval.) | I6: ✅ Partiel : « Lampadaire intelligent » séances 1-2 (C4.1-C4.3) · 🔜 C2.1-C2.2 (Thème 1) | J6: Prob. 6 p.45-50 (l'énergie dans un TGV) · Point méthode 6 p.91 (chaîne d'énergie) | K6: IA Th.1 + Fable | L6: =IFERROR(INDEX('📅 Calendrier'!$A$4:$A$44,MATCH("S3 · séance 1",'📅 Calendrier'!$D$4:$D$44,0))&" ("&INDEX('📅 Calendrier'!$B$4:$B$44,MATCH("S3 · séance 1",'📅 Calendrier'!$D$4:$D$44,0))&")","⚠ hors année !") -> S09 (02/11/2026) | M6: =IFERROR(INDEX('📅 Calendrier'!$A$4:$A$44,MATCH("S3 · séance 4",'📅 Calendrier'!$D$4:$D$44,0))&" ("&INDEX('📅 Calendrier'!$B$4:$B$44,MATCH("S3 · séance 4",'📅 Calendrier'!$D$4:$D$44,0))&")","⚠ hors année !") -> S12 (23/11/2026)
A7: 4 | B7: P2/P3 | C7: Le lampadaire intelligent (1) : chaîne d'information, données et premiers programmes | D7: Comment un objet capte-t-il, décide-t-il, agit-il — et comment le décrire en données ? | E7: Thème 2 | F7: 5e_C4.5, C4.6 + 5e_C6.1, C6.2, C6.3 | G7: 5 | H7: Séance 1 🔁 (simulateur maison) · 2 🏫 (données/descripteurs) · 3-4 🏫 (programme par blocs) · 5 🏠 QCM + 🏫 éval. | I7: ✅ Séquence + QCM 32 q + synthèses (C4.5-C4.6) · 🔜 Îlot 5e_C6 (Fable, même objet-fil) | J7: Prob. 4 p.31-36 (système automatisé) · Prob. 7 p.51-58 (programmer une fonctionnalité) · PM 7 p.92 | K7: Fable (Th. 2) | L7: =IFERROR(INDEX('📅 Calendrier'!$A$4:$A$44,MATCH("S4 · séance 1",'📅 Calendrier'!$D$4:$D$44,0))&" ("&INDEX('📅 Calendrier'!$B$4:$B$44,MATCH("S4 · séance 1",'📅 Calendrier'!$D$4:$D$44,0))&")","⚠ hors année !") -> S13 (30/11/2026) | M7: =IFERROR(INDEX('📅 Calendrier'!$A$4:$A$44,MATCH("S4 · séance 5",'📅 Calendrier'!$D$4:$D$44,0))&" ("&INDEX('📅 Calendrier'!$B$4:$B$44,MATCH("S4 · séance 5",'📅 Calendrier'!$D$4:$D$44,0))&")","⚠ hors année !") -> S18 (18/01/2027)
A8: 5 | B8: P3/P4 | C8: Le lampadaire intelligent (2) : le réseau local du collège | D8: Comment les informations circulent-elles entre les postes du collège ? | E8: Thème 2 | F8: 5e_C4.7, C4.8 | G8: 3 | H8: Séance 1 🏫 (jeu du courrier débranché, enveloppes réelles) · 2 🔁 (schéma actif + simulateur maison) · 3 🏠 QCM ciblé + 🏫 bilan | I8: ✅ Séquence (séances 5) + QCM (8 q ciblées C4.7-C4.8) + synthèses | J8: Point méthode 4 p.89 (adresse IP) · Vers Pix D2/D5 p.103-110, 125-128 | K8: Fable (Th. 2) | L8: =IFERROR(INDEX('📅 Calendrier'!$A$4:$A$44,MATCH("S5 · séance 1",'📅 Calendrier'!$D$4:$D$44,0))&" ("&INDEX('📅 Calendrier'!$B$4:$B$44,MATCH("S5 · séance 1",'📅 Calendrier'!$D$4:$D$44,0))&")","⚠ hors année !") -> S19 (25/01/2027) | M8: =IFERROR(INDEX('📅 Calendrier'!$A$4:$A$44,MATCH("S5 · séance 3",'📅 Calendrier'!$D$4:$D$44,0))&" ("&INDEX('📅 Calendrier'!$B$4:$B$44,MATCH("S5 · séance 3",'📅 Calendrier'!$D$4:$D$44,0))&")","⚠ hors année !") -> S22 (01/03/2027)
A9: 6 | B9: P4 | C9: SOS panne : dépanner un objet technique | D9: Comment identifier et réparer la panne d'un objet technique ? | E9: Thème 2 | F9: 5e_C5.1, C5.2, C5.3 | G9: 4 | H9: Séances 1-2 🏫 (objets à démonter, protocole) · 3 🏫 (découverte imprimante 3D) · 4 🔁 (fiche d'intervention + QCM maison) | I9: 🔜 À produire (Fable — prévu avant le 27/07 si possible, sinon après Conseil) | J9: Prob. 5 p.37-44 (réparer un sac à dos) · Point méthode 5 p.90 (imprimante 3D) | K9: Fable (Th. 2) | L9: =IFERROR(INDEX('📅 Calendrier'!$A$4:$A$44,MATCH("S6 · séance 1",'📅 Calendrier'!$D$4:$D$44,0))&" ("&INDEX('📅 Calendrier'!$B$4:$B$44,MATCH("S6 · séance 1",'📅 Calendrier'!$D$4:$D$44,0))&")","⚠ hors année !") -> S23 (08/03/2027) | M9: =IFERROR(INDEX('📅 Calendrier'!$A$4:$A$44,MATCH("S6 · séance 4",'📅 Calendrier'!$D$4:$D$44,0))&" ("&INDEX('📅 Calendrier'!$B$4:$B$44,MATCH("S6 · séance 4",'📅 Calendrier'!$D$4:$D$44,0))&")","⚠ hors année !") -> S26 (29/03/2027)
A10: 7 | B10: P4/P5 | C10: Mini-projet : concevoir et fabriquer un objet utile | D10: Comment concevoir, fabriquer et programmer un objet répondant à un besoin ? | E10: Thème 3 | F10: 5e_C7.1→C7.6, C8.1→C8.3, C9.1→C9.3 | G10: 6 | H10: Séances 1-5 🏫 (démarche de projet, prototypage) · entre séances 🏠 (recherches, croquis) · 6 🏫 revue de projet | I10: 🔜 À produire (Thème 3) | J10: Prob. 8 p.59-64 · Prob. 9 p.65-70 · Prob. 10 p.71-78 · Prob. 11 p.79-85 · PM 9/11 | K10: IA Thème 3 | L10: =IFERROR(INDEX('📅 Calendrier'!$A$4:$A$44,MATCH("S7 · séance 1",'📅 Calendrier'!$D$4:$D$44,0))&" ("&INDEX('📅 Calendrier'!$B$4:$B$44,MATCH("S7 · séance 1",'📅 Calendrier'!$D$4:$D$44,0))&")","⚠ hors année !") -> S27 (05/04/2027) | M10: =IFERROR(INDEX('📅 Calendrier'!$A$4:$A$44,MATCH("S7 · séance 6",'📅 Calendrier'!$D$4:$D$44,0))&" ("&INDEX('📅 Calendrier'!$B$4:$B$44,MATCH("S7 · séance 6",'📅 Calendrier'!$D$4:$D$44,0))&")","⚠ hors année !") -> S33 (31/05/2027)
F11: Total séances planifiées : | G11: =SUM(G4:G10) -> 29 | H11: + 7 semaines tampon = 36 semaines (voir Calendrier)
L12: Colonnes AUTO : recalculées selon les imprévus saisis dans le Calendrier.
A13: Statuts : ✅ en ligne · 🔜 à produire · 📘 cahier Nathan. Les titres « Lampadaire intelligent » actualisent les supports du référentiel initial (« Un capteur au jardin » / « Réseaux ») : mêmes codes, même objet-fil réutilisé — décision à entériner au Conseil du 28/07.

Sheet S1
A1: GÉNÉRATEUR DE SÉQUENCE 2024 — S1 · Bien démarrer : mon environnement numérique au collège
A2: Thème 1 · P1 · 3 séances de 1 h 30 · Responsable : IA Thème 1 · CANEVAS À REMPLIR par IA Thème 1 (règle : l'IA du thème est seule à modifier)
E3: ◀ Progression | F3: ◀ Accueil
A4: Problématique | B4: Comment organiser et sécuriser mon espace de travail numérique ?
A5: Situation déclenchante | B5: ⚠ À compléter par IA Thème 1 (canevas pré-rempli par Fable — codes, problématique et repères Nathan posés).
A6: Prérequis | B6: —
A7: Éléments pour la synthèse (objectifs) | B7: ⚠ À compléter par IA Thème 1 (canevas pré-rempli par Fable — codes, problématique et repères Nathan posés).
A8: Piste d'évaluation | B8: Grille de suivi personnel de fichiers + questionnaire
A9: Domaines du socle mobilisés | B9: D2, D3 (détail par code dans le tableau des compétences ci-dessous)
A10: CRCN — compétences numériques (Pix) | B10: 1.2 Gérer des données (Niv. 1-2) · 4.1 Sécuriser l'environnement (Niv. 2) · 4.2 Protéger les données personnelles (Niv. 1-2) · 5.2 Évoluer dans un environnement numérique (Niv. 1-2)
A11: Versions 🅰 / 🅱 / 🅲 | B11: ⚠ À compléter par IA Thème 1 (canevas pré-rempli par Fable — codes, problématique et repères Nathan posés).
A12: Liens EPI / parcours | B12: ⚠ À compléter par IA Thème 1 (canevas pré-rempli par Fable — codes, problématique et repères Nathan posés).
A13: Cahier Nathan 5e | B13: Prob. 3 p.23-30 (vie privée) · Point méthode 3 p.88 (arborescence) · Vers Pix D4 p.119-124
A14: Ressources en ligne | B14: 🔜 À produire (Thème 1)
A16: Compétences du programme 2024
